<robot
  name="Monday_export_run1_go">
  <link
    name="palm">
    <inertial>
      <origin
        xyz="0.0080864 0.042367 0.076895"
        rpy="0 0 0" />
      <mass
        value="0.11988" />
      <inertia
        ixx="0.00012204"
        ixy="-1.1575E-07"
        ixz="-8.7731E-06"
        iyy="5.6854E-05"
        iyz="1.0672E-05"
        izz="6.8915E-05" />
    </inertial>
    <visual>
      <origin
        xyz="0 0 0"
        rpy="0 0 0" />
      <geometry>
        <mesh
          filename="package://Monday_export_run1_go/meshes/palm.STL" />
      </geometry>
      <material
        name="">
        <color
          rgba="1 1 1 1" />
      </material>
    </visual>
    <collision>
      <origin
        xyz="0 0 0"
        rpy="0 0 0" />
      <geometry>
        <mesh
          filename="package://Monday_export_run1_go/meshes/palm.STL" />
      </geometry>
    </collision>
  </link>
  <link
    name="t_top_link">
    <inertial>
      <origin
        xyz="0.0085736 -0.0073366 -2.616E-12"
        rpy="0 0 0" />
      <mass
        value="0.0060855" />
      <inertia
        ixx="5.5650E-07"
        ixy="3.9000E-08"
        ixz="0"
        iyy="3.8562E-07"
        iyz="0"
        izz="4.9595E-07" />
    </inertial>
    <visual>
      <origin
        xyz="0 0 0"
        rpy="0 0 0" />
      <geometry>
        <mesh
          filename="package://Monday_export_run1_go/meshes/t_top_link.STL" />
      </geometry>
      <material
        name="">
        <color
          rgba="1 1 1 1" />
      </material>
    </visual>
    <collision>
      <origin
        xyz="0 0 0"
        rpy="0 0 0" />
      <geometry>
        <mesh
          filename="package://Monday_export_run1_go/meshes/t_top_link.STL" />
      </geometry>
    </collision>
  </link>
  <joint
    name="t_top_joint"
    type="revolute">
    <origin
      xyz="0.017288 0.079183 0.046969"
      rpy="-2.6565 5.4287E-17 -1.4972E-17" />
    <parent
      link="palm" />
    <child
      link="t_top_link" />
    <axis
      xyz="1 0 0" />
    <limit
      lower="-0.61"
      upper="0.61"
      effort="4"
      velocity="4" />
  </joint>
  <link
    name="t_fuse_link">
    <inertial>
      <origin
        xyz="0.0013215 0.0015632 0.026497"
        rpy="0 0 0" />
      <mass
        value="0.013726" />
      <inertia
        ixx="2.9313E-06"
        ixy="2.2720E-08"
        ixz="2.7593E-07"
        iyy="3.1174E-06"
        iyz="1.8393E-07"
        izz="8.1416E-07" />
    </inertial>
    <visual>
      <origin
        xyz="0 0 0"
        rpy="0 0 0" />
      <geometry>
        <mesh
          filename="package://Monday_export_run1_go/meshes/t_fuse_link.STL" />
      </geometry>
      <material
        name="">
        <color
          rgba="1 1 1 1" />
      </material>
    </visual>
    <collision>
      <origin
        xyz="0 0 0"
        rpy="0 0 0" />
      <geometry>
        <mesh
          filename="package://Monday_export_run1_go/meshes/t_fuse_link.STL" />
      </geometry>
    </collision>
  </link>
  <joint
    name="t_fuse_joint"
    type="revolute">
    <origin
      xyz="0.0071909 -0.021619 0"
      rpy="-1.5708 -1.5708 -2.007" />
    <parent
      link="t_top_link" />
    <child
      link="t_fuse_link" />
    <axis
      xyz="1 0 0" />
    <limit
      lower="0"
      upper="0.8"
      effort="4"
      velocity="4" />
  </joint>
  <link
    name="t_dp_link">
    <inertial>
      <origin
        xyz="-1.6495E-08 -0.0022565 0.025619"
        rpy="0 0 0" />
      <mass
        value="0.012552" />
      <inertia
        ixx="2.5049E-06"
        ixy="0"
        ixz="0"
        iyy="2.6019E-06"
        iyz="-1.6993E-07"
        izz="5.6836E-07" />
    </inertial>
    <visual>
      <origin
        xyz="0 0 0"
        rpy="0 0 0" />
      <geometry>
        <mesh
          filename="package://Monday_export_run1_go/meshes/t_dp_link.STL" />
      </geometry>
      <material
        name="">
        <color
          rgba="1 1 1 1" />
      </material>
    </visual>
    <collision>
      <origin
        xyz="0 0 0"
        rpy="0 0 0" />
      <geometry>
        <mesh
          filename="package://Monday_export_run1_go/meshes/t_dp_link.STL" />
      </geometry>
    </collision>
  </link>
  <joint
    name="t_dp_joint"
    type="revolute">
    <origin
      xyz="0.0072839 0.0045297 0.053841"
      rpy="-0.02124 0.258 -0.044959" />
    <parent
      link="t_fuse_link" />
    <child
      link="t_dp_link" />
    <axis
      xyz="-1 0 0" />
    <limit
      lower="-1.57"
      upper="0"
      effort="4"
      velocity="4" />
  </joint>
  <link
    name="i_trans_link">
    <inertial>
      <origin
        xyz="-0.0040005 1.9199E-08 0.0064072"
        rpy="0 0 0" />
      <mass
        value="0.0027274" />
      <inertia
        ixx="1.8051E-07"
        ixy="0"
        ixz="-4.8800E-09"
        iyy="1.0870E-07"
        iyz="0"
        izz="1.8693E-07" />
    </inertial>
    <visual>
      <origin
        xyz="0 0 0"
        rpy="0 0 0" />
      <geometry>
        <mesh
          filename="package://Monday_export_run1_go/meshes/i_trans_link.STL" />
      </geometry>
      <material
        name="">
        <color
          rgba="1 1 1 1" />
      </material>
    </visual>
    <collision>
      <origin
        xyz="0 0 0"
        rpy="0 0 0" />
      <geometry>
        <mesh
          filename="package://Monday_export_run1_go/meshes/i_trans_link.STL" />
      </geometry>
    </collision>
  </link>
  <joint
    name="i_trans_joint"
    type="revolute">
    <origin
      xyz="0.016494 0.080177 0.11991"
      rpy="4.0074E-10 -3.9141E-16 2.3427E-16" />
    <parent
      link="palm" />
    <child
      link="i_trans_link" />
    <axis
      xyz="-1 0 0" />
    <limit
      lower="-0.26"
      upper="0.26"
      effort="4"
      velocity="4" />
  </joint>
  <link
    name="i_proximal_link">
    <inertial>
      <origin
        xyz="-6.9569E-08 -0.00018345 0.022146"
        rpy="0 0 0" />
      <mass
        value="0.011601" />
      <inertia
        ixx="2.1443E-06"
        ixy="0"
        ixz="0"
        iyy="2.2182E-06"
        iyz="3.0910E-08"
        izz="6.9839E-07" />
    </inertial>
    <visual>
      <origin
        xyz="0 0 0"
        rpy="0 0 0" />
      <geometry>
        <mesh
          filename="package://Monday_export_run1_go/meshes/i_proximal_link.STL" />
      </geometry>
      <material
        name="">
        <color
          rgba="1 1 1 1" />
      </material>
    </visual>
    <collision>
      <origin
        xyz="0 0 0"
        rpy="0 0 0" />
      <geometry>
        <mesh
          filename="package://Monday_export_run1_go/meshes/i_proximal_link.STL" />
      </geometry>
    </collision>
  </link>
  <joint
    name="i_proximal_joint"
    type="revolute">
    <origin
      xyz="-0.003556 0 0.0127"
      rpy="-1.4086E-12 -1.1737E-16 1.5708" />
    <parent
      link="i_trans_link" />
    <child
      link="i_proximal_link" />
    <axis
      xyz="-1 0 0" />
    <limit
      lower="-1.57"
      upper="0"
      effort="4"
      velocity="4" />
  </joint>
  <link
    name="i_middle_link">
    <inertial>
      <origin
        xyz="9.9295E-09 0.00023385 0.015157"
        rpy="0 0 0" />
      <mass
        value="0.007975" />
      <inertia
        ixx="8.9117E-07"
        ixy="0"
        ixz="0"
        iyy="9.5251E-07"
        iyz="-1.6730E-08"
        izz="4.7759E-07" />
    </inertial>
    <visual>
      <origin
        xyz="0 0 0"
        rpy="0 0 0" />
      <geometry>
        <mesh
          filename="package://Monday_export_run1_go/meshes/i_middle_link.STL" />
      </geometry>
      <material
        name="">
        <color
          rgba="1 1 1 1" />
      </material>
    </visual>
    <collision>
      <origin
        xyz="0 0 0"
        rpy="0 0 0" />
      <geometry>
        <mesh
          filename="package://Monday_export_run1_go/meshes/i_middle_link.STL" />
      </geometry>
    </collision>
  </link>
  <joint
    name="i_middle_joint"
    type="revolute">
    <origin
      xyz="0 0 0.04445"
      rpy="-1.5409E-14 0 -2.7318E-16" />
    <parent
      link="i_proximal_link" />
    <child
      link="i_middle_link" />
    <axis
      xyz="-1 0 0" />
    <limit
      lower="-1.57"
      upper="0"
      effort="4"
      velocity="4" />
  </joint>
  <link
    name="i_dp_link">
    <inertial>
      <origin
        xyz="4.805E-08 5.2937E-05 0.015772"
        rpy="0 0 0" />
      <mass
        value="0.0082292" />
      <inertia
        ixx="7.4000E-07"
        ixy="0"
        ixz="0"
        iyy="7.9356E-07"
        iyz="-1.9940E-08"
        izz="3.9386E-07" />
    </inertial>
    <visual>
      <origin
        xyz="0 0 0"
        rpy="0 0 0" />
      <geometry>
        <mesh
          filename="package://Monday_export_run1_go/meshes/i_dp_link.STL" />
      </geometry>
      <material
        name="">
        <color
          rgba="1 1 1 1" />
      </material>
    </visual>
    <collision>
      <origin
        xyz="0 0 0"
        rpy="0 0 0" />
      <geometry>
        <mesh
          filename="package://Monday_export_run1_go/meshes/i_dp_link.STL" />
      </geometry>
    </collision>
  </link>
  <joint
    name="i_dp_joint"
    type="revolute">
    <origin
      xyz="0 0 0.03175"
      rpy="1.4433E-15 0 -3.2535E-30" />
    <parent
      link="i_middle_link" />
    <child
      link="i_dp_link" />
    <axis
      xyz="-1 0 0" />
    <limit
     lower="-1.57"
      upper="0"
      effort="4"
      velocity="4" />
  </joint>
  <link
    name="m_trans_link">
    <inertial>
      <origin
        xyz="-0.0040005 1.9226E-08 0.0064072"
        rpy="0 0 0" />
      <mass
        value="0.0027274" />
      <inertia
        ixx="1.8051E-07"
        ixy="0"
        ixz="-4.8800E-09"
        iyy="1.0870E-07"
        iyz="0"
        izz="1.8693E-07" />
    </inertial>
    <visual>
      <origin
        xyz="0 0 0"
        rpy="0 0 0" />
      <geometry>
        <mesh
          filename="package://Monday_export_run1_go/meshes/m_trans_link.STL" />
      </geometry>
      <material
        name="">
        <color
          rgba="1 1 1 1" />
      </material>
    </visual>
    <collision>
      <origin
        xyz="0 0 0"
        rpy="0 0 0" />
      <geometry>
        <mesh
          filename="package://Monday_export_run1_go/meshes/m_trans_link.STL" />
      </geometry>
    </collision>
  </link>
  <joint
    name="m_trans_joint"
    type="revolute">
    <origin
      xyz="0.015924 0.051602 0.12618"
      rpy="4.0177E-10 -0.004749 -1.9084E-12" />
    <parent
      link="palm" />
    <child
      link="m_trans_link" />
    <axis
      xyz="-1 0 0" />
    <limit
      lower="-0.26"
      upper="0.26"
      effort="4"
      velocity="4" />
  </joint>
  <link
    name="m_proximal_link">
    <inertial>
      <origin
        xyz="-6.9532E-08 -0.00018345 0.022146"
        rpy="0 0 0" />
      <mass
        value="0.011601" />
      <inertia
        ixx="2.1443E-06"
        ixy="0"
        ixz="0"
        iyy="2.2182E-06"
        iyz="3.0910E-08"
        izz="6.9839E-07" />
    </inertial>
    <visual>
      <origin
        xyz="0 0 0"
        rpy="0 0 0" />
      <geometry>
        <mesh
          filename="package://Monday_export_run1_go/meshes/m_proximal_link.STL" />
      </geometry>
      <material
        name="">
        <color
          rgba="1 1 1 1" />
      </material>
    </visual>
    <collision>
      <origin
        xyz="0 0 0"
        rpy="0 0 0" />
      <geometry>
        <mesh
          filename="package://Monday_export_run1_go/meshes/m_proximal_link.STL" />
      </geometry>
    </collision>
  </link>
  <joint
    name="m_proximal_joint"
    type="revolute">
    <origin
      xyz="-0.003556 0 0.0127"
      rpy="-1.2213E-12 3.3448E-28 1.5708" />
    <parent
      link="m_trans_link" />
    <child
      link="m_proximal_link" />
    <axis
      xyz="-1 0 0" />
    <limit
      lower="-1.57"
      upper="0"
      effort="4"
      velocity="4" />
  </joint>
  <link
    name="m_middle_link">
    <inertial>
      <origin
        xyz="9.8546E-09 0.00023385 0.015157"
        rpy="0 0 0" />
      <mass
        value="0.007975" />
      <inertia
        ixx="8.9117E-07"
        ixy="0"
        ixz="0"
        iyy="9.5251E-07"
        iyz="-1.6730E-08"
        izz="4.7759E-07" />
    </inertial>
    <visual>
      <origin
        xyz="0 0 0"
        rpy="0 0 0" />
      <geometry>
        <mesh
          filename="package://Monday_export_run1_go/meshes/m_middle_link.STL" />
      </geometry>
      <material
        name="">
        <color
          rgba="1 1 1 1" />
      </material>
    </visual>
    <collision>
      <origin
        xyz="0 0 0"
        rpy="0 0 0" />
      <geometry>
        <mesh
          filename="package://Monday_export_run1_go/meshes/m_middle_link.STL" />
      </geometry>
    </collision>
  </link>
  <joint
    name="m_middle_joint"
    type="revolute">
    <origin
      xyz="0 0 0.04445"
      rpy="-1.5395E-14 0 -2.7318E-16" />
    <parent
      link="m_proximal_link" />
    <child
      link="m_middle_link" />
    <axis
      xyz="-1 0 0" />
    <limit
     lower="-1.57"
      upper="0"
      effort="4"
      velocity="4" />
  </joint>
  <link
    name="m_dp_link">
    <inertial>
      <origin
        xyz="4.805E-08 5.2937E-05 0.015772"
        rpy="0 0 0" />
      <mass
        value="0.0082292" />
      <inertia
        ixx="7.4000E-07"
        ixy="0"
        ixz="0"
        iyy="7.9356E-07"
        iyz="-1.9940E-08"
        izz="3.9386E-07" />
    </inertial>
    <visual>
      <origin
        xyz="0 0 0"
        rpy="0 0 0" />
      <geometry>
        <mesh
          filename="package://Monday_export_run1_go/meshes/m_dp_link.STL" />
      </geometry>
      <material
        name="">
        <color
          rgba="1 1 1 1" />
      </material>
    </visual>
    <collision>
      <origin
        xyz="0 0 0"
        rpy="0 0 0" />
      <geometry>
        <mesh
          filename="package://Monday_export_run1_go/meshes/m_dp_link.STL" />
      </geometry>
    </collision>
  </link>
  <joint
    name="m_dp_joint"
    type="revolute">
    <origin
      xyz="0 0 0.03175"
      rpy="1.4225E-15 2.3666E-30 -3.4513E-31" />
    <parent
      link="m_middle_link" />
    <child
      link="m_dp_link" />
    <axis
      xyz="-1 0 0" />
    <limit
      lower="-1.57"
      upper="0"
      effort="4"
      velocity="4" />
  </joint>
  <link
    name="r_trans_link">
    <inertial>
      <origin
        xyz="-0.0040005 1.9191E-08 0.0064072"
        rpy="0 0 0" />
      <mass
        value="0.0027274" />
      <inertia
        ixx="1.8051E-07"
        ixy="0"
        ixz="-4.8800E-09"
        iyy="1.0870E-07"
        iyz="0"
        izz="1.8693E-07" />
    </inertial>
    <visual>
      <origin
        xyz="0 0 0"
        rpy="0 0 0" />
      <geometry>
        <mesh
          filename="package://Monday_export_run1_go/meshes/r_trans_link.STL" />
      </geometry>
      <material
        name="">
        <color
          rgba="1 1 1 1" />
      </material>
    </visual>
    <collision>
      <origin
        xyz="0 0 0"
        rpy="0 0 0" />
      <geometry>
        <mesh
          filename="package://Monday_export_run1_go/meshes/r_trans_link.STL" />
      </geometry>
    </collision>
  </link>
  <joint
    name="r_trans_joint"
    type="revolute">
    <origin
      xyz="0.016573 0.023027 0.11945"
      rpy="4.0176E-10 0.00066029 6.9104E-13" />
    <parent
      link="palm" />
    <child
      link="r_trans_link" />
    <axis
      xyz="-1 0 0" />
    <limit
      lower="-0.26"
      upper="0.26"
      effort="4"
      velocity="4" />
  </joint>
  <link
    name="r_proximal_link">
    <inertial>
      <origin
        xyz="-6.9566E-08 -0.00018345 0.022146"
        rpy="0 0 0" />
      <mass
        value="0.011601" />
      <inertia
        ixx="2.1443E-06"
        ixy="0"
        ixz="0"
        iyy="2.2182E-06"
        iyz="3.0910E-08"
        izz="6.9839E-07" />
    </inertial>
    <visual>
      <origin
        xyz="0 0 0"
        rpy="0 0 0" />
      <geometry>
        <mesh
          filename="package://Monday_export_run1_go/meshes/r_proximal_link.STL" />
      </geometry>
      <material
        name="">
        <color
          rgba="1 1 1 1" />
      </material>
    </visual>
    <collision>
      <origin
        xyz="0 0 0"
        rpy="0 0 0" />
      <geometry>
        <mesh
          filename="package://Monday_export_run1_go/meshes/r_proximal_link.STL" />
      </geometry>
    </collision>
  </link>
  <joint
    name="r_proximal_joint"
    type="revolute">
    <origin
      xyz="-0.003556 0 0.0127"
      rpy="-1.0227E-12 -1.1735E-16 1.5708" />
    <parent
      link="r_trans_link" />
    <child
      link="r_proximal_link" />
    <axis
      xyz="-1 0 0" />
    <limit
      lower="-1.57"
      upper="0"
      effort="4"
      velocity="4" />
  </joint>
  <link
    name="r_middle_link">
    <inertial>
      <origin
        xyz="9.9112E-09 0.00023385 0.015157"
        rpy="0 0 0" />
      <mass
        value="0.007975" />
      <inertia
        ixx="8.9117E-07"
        ixy="0"
        ixz="0"
        iyy="9.5251E-07"
        iyz="-1.6730E-08"
        izz="4.7759E-07" />
    </inertial>
    <visual>
      <origin
        xyz="0 0 0"
        rpy="0 0 0" />
      <geometry>
        <mesh
          filename="package://Monday_export_run1_go/meshes/r_middle_link.STL" />
      </geometry>
      <material
        name="">
        <color
          rgba="1 1 1 1" />
      </material>
    </visual>
    <collision>
      <origin
        xyz="0 0 0"
        rpy="0 0 0" />
      <geometry>
        <mesh
          filename="package://Monday_export_run1_go/meshes/r_middle_link.STL" />
      </geometry>
    </collision>
  </link>
  <joint
    name="r_middle_joint"
    type="revolute">
    <origin
      xyz="0 0 0.04445"
      rpy="-5.6948E-15 0 -2.7318E-16" />
    <parent
      link="r_proximal_link" />
    <child
      link="r_middle_link" />
    <axis
      xyz="-1 0 0" />
    <limit
      lower="-1.57"
      upper="0"
      effort="4"
      velocity="4" />
  </joint>
  <link
    name="r_dp_link">
    <inertial>
      <origin
        xyz="5.3058E-08 5.2932E-05 0.015772"
        rpy="0 0 0" />
      <mass
        value="0.0082292" />
      <inertia
        ixx="7.4000E-07"
        ixy="0"
        ixz="0"
        iyy="7.9356E-07"
        iyz="-1.9940E-08"
        izz="3.9386E-07" />
    </inertial>
    <visual>
      <origin
        xyz="0 0 0"
        rpy="0 0 0" />
      <geometry>
        <mesh
          filename="package://Monday_export_run1_go/meshes/r_dp_link.STL" />
      </geometry>
      <material
        name="">
        <color
          rgba="1 1 1 1" />
      </material>
    </visual>
    <collision>
      <origin
        xyz="0 0 0"
        rpy="0 0 0" />
      <geometry>
        <mesh
          filename="package://Monday_export_run1_go/meshes/r_dp_link.STL" />
      </geometry>
    </collision>
  </link>
  <joint
    name="r_dp_joint"
    type="revolute">
    <origin
      xyz="0 0 0.03175"
      rpy="-7.3205E-15 1.5777E-30 4.6732E-29" />
    <parent
      link="r_middle_link" />
    <child
      link="r_dp_link" />
    <axis
      xyz="-1 0 0" />
    <limit
      lower="-1.57"
      upper="0"
      effort="4"
      velocity="4" />
  </joint>
  <link
    name="p_trans_link">
    <inertial>
      <origin
        xyz="-0.0040005 1.9191E-08 0.0064072"
        rpy="0 0 0" />
      <mass
        value="0.0027274" />
      <inertia
        ixx="1.8051E-07"
        ixy="0"
        ixz="-4.8800E-09"
        iyy="1.0870E-07"
        iyz="0"
        izz="1.8693E-07" />
    </inertial>
    <visual>
      <origin
        xyz="0 0 0"
        rpy="0 0 0" />
      <geometry>
        <mesh
          filename="package://Monday_export_run1_go/meshes/r_trans_link.STL" />
      </geometry>
      <material
        name="">
        <color
          rgba="1 1 1 1" />
      </material>
    </visual>
    <collision>
      <origin
        xyz="0 0 0"
        rpy="0 0 0" />
      <geometry>
        <mesh
          filename="package://Monday_export_run1_go/meshes/r_trans_link.STL" />
      </geometry>
    </collision>
  </link>
  <joint
    name="p_trans_joint"
    type="revolute">
    <origin
      xyz="0.016494 -0.0055477 0.11509"
      rpy="4.0176E-10 -5.2758E-16 -3.3357E-16" />
    <parent
      link="palm" />
    <child
      link="p_trans_link" />
    <axis
      xyz="-1 0 0" />
    <limit
      lower="-0.26"
      upper="0.26"
      effort="4"
      velocity="4" />
  </joint>
  <link
    name="p_proximal_link">
    <inertial>
      <origin
        xyz="9.9295E-09 0.00023385 0.015157"
        rpy="0 0 0" />
      <mass
        value="0.007975" />
      <inertia
        ixx="8.9117E-07"
        ixy="0"
        ixz="0"
        iyy="9.5251E-07"
        iyz="-1.6730E-08"
        izz="4.7759E-07" />
    </inertial>
    <visual>
      <origin
        xyz="0 0 0"
        rpy="0 0 0" />
      <geometry>
        <mesh
          filename="package://Monday_export_run1_go/meshes/p_middle_link.STL" />
      </geometry>
      <material
        name="">
        <color
          rgba="1 1 1 1" />
      </material>
    </visual>
    <collision>
      <origin
        xyz="0 0 0"
        rpy="0 0 0" />
      <geometry>
        <mesh
          filename="package://Monday_export_run1_go/meshes/p_middle_link.STL" />
      </geometry>
    </collision>
  </link>
  <joint
    name="p_proximal_joint"
    type="revolute">
    <origin
      xyz="-0.003556 0 0.0127"
      rpy="-1.2438E-12 1.7202E-26 1.5708" />
    <parent
      link="p_trans_link" />
    <child
      link="p_proximal_link" />
    <axis
      xyz="-1 0 0" />
    <limit
     lower="-1.57"
      upper="0"
      effort="4"
      velocity="4" />
  </joint>
  <link
    name="p_middle_link">
    <inertial>
      <origin
        xyz="9.9295E-09 0.00023385 0.015157"
        rpy="0 0 0" />
      <mass
        value="0.007975" />
      <inertia
        ixx="8.9117E-07"
        ixy="0"
        ixz="0"
        iyy="9.5251E-07"
        iyz="-1.6730E-08"
        izz="4.7759E-07" />
    </inertial>
    <visual>
      <origin
        xyz="0 0 0"
        rpy="0 0 0" />
      <geometry>
        <mesh
          filename="package://Monday_export_run1_go/meshes/p_middle_link.STL" />
      </geometry>
      <material
        name="">
        <color
          rgba="1 1 1 1" />
      </material>
    </visual>
    <collision>
      <origin
        xyz="0 0 0"
        rpy="0 0 0" />
      <geometry>
        <mesh
          filename="package://Monday_export_run1_go/meshes/p_middle_link.STL" />
      </geometry>
    </collision>
  </link>
  <joint
    name="p_middle_joint"
    type="revolute">
    <origin
      xyz="0 0 0.03175"
      rpy="6.983E-15 -6.983E-15 -1.3966E-14" />
    <parent
      link="p_proximal_link" />
    <child
      link="p_middle_link" />
    <axis
      xyz="-1 0 0" />
    <limit
      lower="-1.57"
      upper="0"
      effort="4"
      velocity="4" />
  </joint>
  <link
    name="p_dp_link">
    <inertial>
      <origin
        xyz="4.805E-08 5.2937E-05 0.015772"
        rpy="0 0 0" />
      <mass
        value="0.0082292" />
      <inertia
        ixx="7.4000E-07"
        ixy="0"
        ixz="0"
        iyy="7.9356E-07"
        iyz="-1.9940E-08"
        izz="3.9386E-07" />
    </inertial>
    <visual>
      <origin
        xyz="0 0 0"
        rpy="0 0 0" />
      <geometry>
        <mesh
          filename="package://Monday_export_run1_go/meshes/p_dp_link.STL" />
      </geometry>
      <material
        name="">
        <color
          rgba="1 1 1 1" />
      </material>
    </visual>
    <collision>
      <origin
        xyz="0 0 0"
        rpy="0 0 0" />
      <geometry>
        <mesh
          filename="package://Monday_export_run1_go/meshes/p_dp_link.STL" />
      </geometry>
    </collision>
  </link>
  <joint
    name="p_dp_joint"
    type="revolute">
    <origin
      xyz="0 0 0.03175"
      rpy="0 0 1.7025E-43" />
    <parent
      link="p_middle_link" />
    <child
      link="p_dp_link" />
    <axis
      xyz="-1 0 0" />
    <limit
     lower="-1.57"
      upper="0"
      effort="4"
      velocity="4" />
  </joint>
</robot>
